Traceback (most recent call last):
  File "/usr/local/lib/python3.11/dist-packages/jupyter_core/utils/__init__.py", line 154, in wrapped
    asyncio.get_running_loop()
RuntimeError: no running event loop

During handling of the above exception, another exception occurred:

Traceback (most recent call last):
  File "/usr/local/lib/python3.11/dist-packages/jupyter_cache/executors/utils.py", line 58, in single_nb_execution
    executenb(
  File "/usr/local/lib/python3.11/dist-packages/nbclient/client.py", line 1319, in execute
    return NotebookClient(nb=nb, resources=resources, km=km, **kwargs).execute()
           ^^^^^^^^^^^^^^^^^^^^^^^^^^^^^^^^^^^^^^^^^^^^^^^^^^^^^^^^^^^^^^^^^^^^^
  File "/usr/local/lib/python3.11/dist-packages/jupyter_core/utils/__init__.py", line 158, in wrapped
    return loop.run_until_complete(inner)
           ^^^^^^^^^^^^^^^^^^^^^^^^^^^^^^
  File "/usr/lib/python3.11/asyncio/base_events.py", line 654, in run_until_complete
    return future.result()
           ^^^^^^^^^^^^^^^
  File "/usr/local/lib/python3.11/dist-packages/nbclient/client.py", line 709, in async_execute
    await self.async_execute_cell(
  File "/usr/local/lib/python3.11/dist-packages/nbclient/client.py", line 1062, in async_execute_cell
    await self._check_raise_for_error(cell, cell_index, exec_reply)
  File "/usr/local/lib/python3.11/dist-packages/nbclient/client.py", line 918, in _check_raise_for_error
    raise CellExecutionError.from_cell_and_msg(cell, exec_reply_content)
nbclient.exceptions.CellExecutionError: An error occurred while executing the following cell:
------------------
import pymysql

# Konfigurasi koneksi
host = "mysqlpendata-ilhamalmafazt-dm.h.aivencloud.com"  # Ganti host dengan host dari Aiven.io
port = 19867
user = "avnadmin"
password = "AVNS_vnxDk9lOvZgFnuKlezN"
database = "defaultdb"

# Buat koneksi
mysql_conn = pymysql.connect(
    host=host,
    port=port,
    user=user,
    password=password,
    database=database,
    ssl={'ssl': {}}  # Jika menggunakan SSL
)

cursor = mysql_conn.cursor()
cursor.execute("SELECT * FROM iris_sql.iris LIMIT 5;")
tampil = cursor.fetchall()
for data in tampil:
    print(data)
mysql_conn.close()

------------------


[0;31m---------------------------------------------------------------------------[0m
[0;31mgaierror[0m                                  Traceback (most recent call last)
[0;32m/usr/local/lib/python3.11/dist-packages/pymysql/connections.py[0m in [0;36mconnect[0;34m(self, sock)[0m
[1;32m    648[0m                         [0;32mtry[0m[0;34m:[0m[0;34m[0m[0;34m[0m[0m
[0;32m--> 649[0;31m                             sock = socket.create_connection(
[0m[1;32m    650[0m                                 [0;34m([0m[0mself[0m[0;34m.[0m[0mhost[0m[0;34m,[0m [0mself[0m[0;34m.[0m[0mport[0m[0;34m)[0m[0;34m,[0m [0mself[0m[0;34m.[0m[0mconnect_timeout[0m[0;34m,[0m [0;34m**[0m[0mkwargs[0m[0;34m[0m[0;34m[0m[0m

[0;32m/usr/lib/python3.11/socket.py[0m in [0;36mcreate_connection[0;34m(address, timeout, source_address, all_errors)[0m
[1;32m    838[0m     [0mexceptions[0m [0;34m=[0m [0;34m[[0m[0;34m][0m[0;34m[0m[0;34m[0m[0m
[0;32m--> 839[0;31m     [0;32mfor[0m [0mres[0m [0;32min[0m [0mgetaddrinfo[0m[0;34m([0m[0mhost[0m[0;34m,[0m [0mport[0m[0;34m,[0m [0;36m0[0m[0;34m,[0m [0mSOCK_STREAM[0m[0;34m)[0m[0;34m:[0m[0;34m[0m[0;34m[0m[0m
[0m[1;32m    840[0m         [0maf[0m[0;34m,[0m [0msocktype[0m[0;34m,[0m [0mproto[0m[0;34m,[0m [0mcanonname[0m[0;34m,[0m [0msa[0m [0;34m=[0m [0mres[0m[0;34m[0m[0;34m[0m[0m

[0;32m/usr/lib/python3.11/socket.py[0m in [0;36mgetaddrinfo[0;34m(host, port, family, type, proto, flags)[0m
[1;32m    973[0m     [0maddrlist[0m [0;34m=[0m [0;34m[[0m[0;34m][0m[0;34m[0m[0;34m[0m[0m
[0;32m--> 974[0;31m     [0;32mfor[0m [0mres[0m [0;32min[0m [0m_socket[0m[0;34m.[0m[0mgetaddrinfo[0m[0;34m([0m[0mhost[0m[0;34m,[0m [0mport[0m[0;34m,[0m [0mfamily[0m[0;34m,[0m [0mtype[0m[0;34m,[0m [0mproto[0m[0;34m,[0m [0mflags[0m[0;34m)[0m[0;34m:[0m[0;34m[0m[0;34m[0m[0m
[0m[1;32m    975[0m         [0maf[0m[0;34m,[0m [0msocktype[0m[0;34m,[0m [0mproto[0m[0;34m,[0m [0mcanonname[0m[0;34m,[0m [0msa[0m [0;34m=[0m [0mres[0m[0;34m[0m[0;34m[0m[0m

[0;31mgaierror[0m: [Errno -2] Name or service not known

During handling of the above exception, another exception occurred:

[0;31mOperationalError[0m                          Traceback (most recent call last)
[0;32m/tmp/ipython-input-2-2754774254.py[0m in [0;36m<cell line: 0>[0;34m()[0m
[1;32m      9[0m [0;34m[0m[0m
[1;32m     10[0m [0;31m# Buat koneksi[0m[0;34m[0m[0;34m[0m[0m
[0;32m---> 11[0;31m mysql_conn = pymysql.connect(
[0m[1;32m     12[0m     [0mhost[0m[0;34m=[0m[0mhost[0m[0;34m,[0m[0;34m[0m[0;34m[0m[0m
[1;32m     13[0m     [0mport[0m[0;34m=[0m[0mport[0m[0;34m,[0m[0;34m[0m[0;34m[0m[0m

[0;32m/usr/local/lib/python3.11/dist-packages/pymysql/connections.py[0m in [0;36m__init__[0;34m(self, user, password, host, database, unix_socket, port, charset, collation, sql_mode, read_default_file, conv, use_unicode, client_flag, cursorclass, init_command, connect_timeout, read_default_group, autocommit, local_infile, max_allowed_packet, defer_connect, auth_plugin_map, read_timeout, write_timeout, bind_address, binary_prefix, program_name, server_public_key, ssl, ssl_ca, ssl_cert, ssl_disabled, ssl_key, ssl_key_password, ssl_verify_cert, ssl_verify_identity, compress, named_pipe, passwd, db)[0m
[1;32m    359[0m             [0mself[0m[0;34m.[0m[0m_sock[0m [0;34m=[0m [0;32mNone[0m[0;34m[0m[0;34m[0m[0m
[1;32m    360[0m         [0;32melse[0m[0;34m:[0m[0;34m[0m[0;34m[0m[0m
[0;32m--> 361[0;31m             [0mself[0m[0;34m.[0m[0mconnect[0m[0;34m([0m[0;34m)[0m[0;34m[0m[0;34m[0m[0m
[0m[1;32m    362[0m [0;34m[0m[0m
[1;32m    363[0m     [0;32mdef[0m [0m__enter__[0m[0;34m([0m[0mself[0m[0;34m)[0m[0;34m:[0m[0;34m[0m[0;34m[0m[0m

[0;32m/usr/local/lib/python3.11/dist-packages/pymysql/connections.py[0m in [0;36mconnect[0;34m(self, sock)[0m
[1;32m    714[0m                 [0;32mif[0m [0mDEBUG[0m[0;34m:[0m[0;34m[0m[0;34m[0m[0m
[1;32m    715[0m                     [0mprint[0m[0;34m([0m[0mexc[0m[0;34m.[0m[0mtraceback[0m[0;34m)[0m[0;34m[0m[0;34m[0m[0m
[0;32m--> 716[0;31m                 [0;32mraise[0m [0mexc[0m[0;34m[0m[0;34m[0m[0m
[0m[1;32m    717[0m [0;34m[0m[0m
[1;32m    718[0m             [0;31m# If e is neither DatabaseError or IOError, It's a bug.[0m[0;34m[0m[0;34m[0m[0m

[0;31mOperationalError[0m: (2003, "Can't connect to MySQL server on 'mysqlpendata-ilhamalmafazt-dm.h.aivencloud.com' ([Errno -2] Name or service not known)")

